3/17/2020 11:27:2

Traceback (most recent call last):
  File "C:\Users\Nick\AppData\Local\Programs\Python\Python36\lib\site-packages\aiohttp\connector.py", line 967, in _create_direct_connection
    traces=traces), loop=self._loop)
  File "C:\Users\Nick\AppData\Local\Programs\Python\Python36\lib\site-packages\aiohttp\connector.py", line 830, in _resolve_host
    self._resolver.resolve(host, port, family=self._family)
  File "C:\Users\Nick\AppData\Local\Programs\Python\Python36\lib\site-packages\aiohttp\resolver.py", line 30, in resolve
    host, port, type=socket.SOCK_STREAM, family=family)
  File "C:\Users\Nick\AppData\Local\Programs\Python\Python36\lib\concurrent\futures\thread.py", line 55, in run
    result = self.fn(*self.args, **self.kwargs)
  File "C:\Users\Nick\AppData\Local\Programs\Python\Python36\lib\socket.py", line 743, in getaddrinfo
    for res in _socket.getaddrinfo(host, port, family, type, proto, flags):
socket.gaierror: [Errno 11001] getaddrinfo failed

The above exception was the direct cause of the following exception:

Traceback (most recent call last):
  File "C:\Users\Nick\Desktop\DiscordBot\discordbot.py", line 277, in <module>
    client.loop.run_until_complete(client.start("Mjk2MjAxMTA2NjEzMjA3MDQx.XPndFw.g-gMDqJHsVLul5x2WMlFMT-LuO0"))
  File "C:\Users\Nick\AppData\Local\Programs\Python\Python36\lib\asyncio\base_events.py", line 466, in run_until_complete
    return future.result()
  File "C:\Users\Nick\AppData\Local\Programs\Python\Python36\lib\site-packages\discord\client.py", line 584, in start
    await self.login(*args, bot=bot)
  File "C:\Users\Nick\AppData\Local\Programs\Python\Python36\lib\site-packages\discord\client.py", line 442, in login
    await self.http.static_login(token.strip(), bot=bot)
  File "C:\Users\Nick\AppData\Local\Programs\Python\Python36\lib\site-packages\discord\http.py", line 261, in static_login
    data = await self.request(Route('GET', '/users/@me'))
  File "C:\Users\Nick\AppData\Local\Programs\Python\Python36\lib\site-packages\discord\http.py", line 165, in request
    async with self.__session.request(method, url, **kwargs) as r:
  File "C:\Users\Nick\AppData\Local\Programs\Python\Python36\lib\site-packages\aiohttp\client.py", line 1012, in __aenter__
    self._resp = await self._coro
  File "C:\Users\Nick\AppData\Local\Programs\Python\Python36\lib\site-packages\aiohttp\client.py", line 483, in _request
    timeout=real_timeout
  File "C:\Users\Nick\AppData\Local\Programs\Python\Python36\lib\site-packages\aiohttp\connector.py", line 523, in connect
    proto = await self._create_connection(req, traces, timeout)
  File "C:\Users\Nick\AppData\Local\Programs\Python\Python36\lib\site-packages\aiohttp\connector.py", line 859, in _create_connection
    req, traces, timeout)
  File "C:\Users\Nick\AppData\Local\Programs\Python\Python36\lib\site-packages\aiohttp\connector.py", line 971, in _create_direct_connection
    raise ClientConnectorError(req.connection_key, exc) from exc
aiohttp.client_exceptions.ClientConnectorError: Cannot connect to host discordapp.com:443 ssl:default [getaddrinfo failed]


